Workbook

Sheet 询价单
A1: 万鼎国际集团 VANTSING INTERNATIONAL GROUP | G1: 报价单 QUATATION | P1: =_xlfn.DISPIMG("ID_2AB6C2DF03EC4B189D9084FA977CA6E6",1) -> =DISPIMG("ID_2AB6C2DF03EC4B189D9084FA977CA6E6",1)
A2: Nomor urut 序号 | B2: Nama Permintaan Barang 询价货物名称 | C2: Spesifikasi dan Model Permintaan Barang 询价规格型号 | D2: Satuan 单位 | E2: Jumlah 数量 | F2: picture 图片 | G2: Product number 产品编号 | H2: Nama Penawaran Barang 报价名称 | J2: Spesifikasi Penawaran Barang 报价产品规格 | K2: Satuan 单位 | L2: Jumlah 数量 | M2: brand 品牌 | N2: Harga 单价 | O2: 总价 | P2: Tanggal Pengiriman Barang 交货日期 | Q2: Gambar Barang 报价产品图片 | R2: NOTE 备注
A3: 1 | B3: 法兰 | C3: DN125 | E3: 3 | G3: 无货
A4: 2 | B4: 法兰 | C4: DN100 | E4: 12 | G4: 8010071335 | H4: =VLOOKUP(G4,[1]LESSO管材!$C:$D,2,FALSE) -> 法兰套(PPR 配件)印尼绿色 dn110 (4") 联塑 | I4: =VLOOKUP(G4,[1]LESSO管材!$C:$E,3,FALSE) -> PPR Stub Flange dn110 (4") Green(INA) - LESSO | K4: 个 | L4: 12 | M4: 联塑 | N4: =VLOOKUP(G4,[1]LESSO管材!$C:$L,10,FALSE) -> 58843 | O4: =N4*L4 -> 706116 | S4: {=INDEX([3]LESSO管材!$H:$H,MATCH(G4,[3]LESSO管材!$C:$C,0))} -> 52959 | T4: =S4*L4 -> 635508 | U4: =(O4-T4)/O4 -> 0.099994902
G5: DS70232 | H5: =VLOOKUP(G5,[1]LESSO管材!$C:$D,2,FALSE) -> dn110 法兰（钢托盘）- DS | I5: =VLOOKUP(G5,[1]LESSO管材!$C:$E,3,FALSE) -> dn110 Flange (Steel Tray) - DS | K5: 个 | L5: 12 | N5: =VLOOKUP(G5,[1]LESSO管材!$C:$L,10,FALSE) -> 141250 | O5: =N5*L5 -> 1695000 | S5: {=INDEX([3]LESSO管材!$H:$H,MATCH(G5,[3]LESSO管材!$C:$C,0))} -> 113000 | T5: =S5*L5 -> 1356000 | U5: =(O5-T5)/O5 -> 0.2
G6: 8010070747 | H6: =VLOOKUP(G6,[1]LESSO管材!$C:$D,2,FALSE) -> 法兰橡胶垫圈(PPR 配件)黑色 dn110 (4") 联塑 | I6: =VLOOKUP(G6,[1]LESSO管材!$C:$E,3,FALSE) -> PPR Rubber Gasket dn110 (4") Black - LESSO | K6: 个 | L6: 12 | M6: 联塑 | N6: =VLOOKUP(G6,[1]LESSO管材!$C:$L,10,FALSE) -> 7443 | O6: =N6*L6 -> 89316 | S6: {=INDEX([3]LESSO管材!$H:$H,MATCH(G6,[3]LESSO管材!$C:$C,0))} -> 6699 | T6: =S6*L6 -> 80388 | U6: =(O6-T6)/O6 -> 0.099959694
G7: 6900010080151 | H7: =VLOOKUP(G7,[1]LESSO管材!$C:$D,2,FALSE) -> 4.8级镀锌（一套8个螺栓） | I7: =VLOOKUP(G7,[1]LESSO管材!$C:$E,3,FALSE) -> 4.8 hex bolt+nut M16 X 100 MM (dn90, dn110) (Galvanis) | K7: 个 | L7: =12*8 -> 96 | N7: =VLOOKUP(G7,[1]LESSO管材!$C:$L,10,FALSE) -> 9440 | O7: =N7*L7 -> 906240 | S7: {=INDEX([3]LESSO管材!$H:$H,MATCH(G7,[3]LESSO管材!$C:$C,0))} -> 4720 | T7: =S7*L7 -> 453120 | U7: =(O7-T7)/O7 -> 0.5
A8: 3 | B8: 法兰 | C8: DN50 | E8: 6 | G8: 8010071332 | H8: =VLOOKUP(G8,[1]LESSO管材!$C:$D,2,FALSE) -> 法兰套(PPR 配件)印尼绿色 dn50 (1-1/2") 联塑 | I8: =VLOOKUP(G8,[1]LESSO管材!$C:$E,3,FALSE) -> PPR Stub Flange dn50 (1-1/2") Green(INA) - LESSO | K8: 个 | L8: 6 | M8: 联塑 | N8: =VLOOKUP(G8,[1]LESSO管材!$C:$L,10,FALSE) -> 9558 | O8: =N8*L8 -> 57348 | S8: {=INDEX([3]LESSO管材!$H:$H,MATCH(G8,[3]LESSO管材!$C:$C,0))} -> 8602 | T8: =S8*L8 -> 51612 | U8: =(O8-T8)/O8 -> 0.10002092
G9: DS70235 | H9: =VLOOKUP(G9,[1]LESSO管材!$C:$D,2,FALSE) -> dn50 法兰（钢托盘）- DS | I9: =VLOOKUP(G9,[1]LESSO管材!$C:$E,3,FALSE) -> dn50 Flange (Steel Tray) - DS | K9: 个 | L9: 6 | N9: =VLOOKUP(G9,[1]LESSO管材!$C:$L,10,FALSE) -> 49375 | O9: =N9*L9 -> 296250 | S9: {=INDEX([3]LESSO管材!$H:$H,MATCH(G9,[3]LESSO管材!$C:$C,0))} -> 39500 | T9: =S9*L9 -> 237000 | U9: =(O9-T9)/O9 -> 0.2
G10: 8010070750 | H10: =VLOOKUP(G10,[1]LESSO管材!$C:$D,2,FALSE) -> 法兰橡胶垫圈(PPR 配件)黑色 dn50 (1-1/2") 联塑 | I10: =VLOOKUP(G10,[1]LESSO管材!$C:$E,3,FALSE) -> PPR Rubber Gasket dn50 (1-1/2") Black - LESSO | K10: 个 | L10: 6 | M10: 联塑 | N10: =VLOOKUP(G10,[1]LESSO管材!$C:$L,10,FALSE) -> 3915 | O10: =N10*L10 -> 23490 | S10: {=INDEX([3]LESSO管材!$H:$H,MATCH(G10,[3]LESSO管材!$C:$C,0))} -> 3132 | T10: =S10*L10 -> 18792 | U10: =(O10-T10)/O10 -> 0.2
G11: 6900010080150 | H11: =VLOOKUP(G11,[1]LESSO管材!$C:$D,2,FALSE) -> 4.8级镀锌（一套4个螺栓） | I11: =VLOOKUP(G11,[1]LESSO管材!$C:$E,3,FALSE) -> 4.8 hex bolt+nut M16 X 80 MM (dn40,50,63,75) (Galvanis) | K11: 个 | L11: 24 | N11: =VLOOKUP(G11,[1]LESSO管材!$C:$L,10,FALSE) -> 8100 | O11: =N11*L11 -> 194400 | S11: {=INDEX([3]LESSO管材!$H:$H,MATCH(G11,[3]LESSO管材!$C:$C,0))} -> 4050 | T11: =S11*L11 -> 97200 | U11: =(O11-T11)/O11 -> 0.5
A12: 4 | B12: 法兰 | C12: DN40 | E12: 6 | G12: 8010071331 | H12: =VLOOKUP(G12,[1]LESSO管材!$C:$D,2,FALSE) -> 法兰套(PPR 配件)印尼绿色 dn40 (1-1/4") 联塑 | I12: =VLOOKUP(G12,[1]LESSO管材!$C:$E,3,FALSE) -> PPR Stub Flange dn40 (1-1/4") Green(INA) - LESSO | K12: 个 | L12: 6 | M12: 联塑 | N12: =VLOOKUP(G12,[1]LESSO管材!$C:$L,10,FALSE) -> 6562 | O12: =N12*L12 -> 39372 | S12: {=INDEX([3]LESSO管材!$H:$H,MATCH(G12,[3]LESSO管材!$C:$C,0))} -> 5906 | T12: =S12*L12 -> 35436 | U12: =(O12-T12)/O12 -> 0.099969521
G13: DS70234 | H13: =VLOOKUP(G13,[1]LESSO管材!$C:$D,2,FALSE) -> dn40 法兰（钢托盘）- DS | I13: =VLOOKUP(G13,[1]LESSO管材!$C:$E,3,FALSE) -> dn40 Flange (Steel Tray) - DS | K13: 个 | L13: 6 | N13: =VLOOKUP(G13,[1]LESSO管材!$C:$L,10,FALSE) -> 41875 | O13: =N13*L13 -> 251250 | S13: {=INDEX([3]LESSO管材!$H:$H,MATCH(G13,[3]LESSO管材!$C:$C,0))} -> 33500 | T13: =S13*L13 -> 201000 | U13: =(O13-T13)/O13 -> 0.2
G14: 8010070749 | H14: =VLOOKUP(G14,[1]LESSO管材!$C:$D,2,FALSE) -> 法兰橡胶垫圈(PPR 配件)黑色 dn40 (1-1/4") 联塑 | I14: =VLOOKUP(G14,[1]LESSO管材!$C:$E,3,FALSE) -> PPR Rubber Gasket dn40 (1-1/4") Black - LESSO | K14: 个 | L14: 6 | M14: 联塑 | N14: =VLOOKUP(G14,[1]LESSO管材!$C:$L,10,FALSE) -> 2081 | O14: =N14*L14 -> 12486 | S14: {=INDEX([3]LESSO管材!$H:$H,MATCH(G14,[3]LESSO管材!$C:$C,0))} -> 1665 | T14: =S14*L14 -> 9990 | U14: =(O14-T14)/O14 -> 0.19990389
G15: 6900010080150 | H15: =VLOOKUP(G15,[1]LESSO管材!$C:$D,2,FALSE) -> 4.8级镀锌（一套4个螺栓） | I15: =VLOOKUP(G15,[1]LESSO管材!$C:$E,3,FALSE) -> 4.8 hex bolt+nut M16 X 80 MM (dn40,50,63,75) (Galvanis) | K15: 个 | L15: 24 | N15: =VLOOKUP(G15,[1]LESSO管材!$C:$L,10,FALSE) -> 8100 | O15: =N15*L15 -> 194400 | S15: {=INDEX([3]LESSO管材!$H:$H,MATCH(G15,[3]LESSO管材!$C:$C,0))} -> 4050 | T15: =S15*L15 -> 97200 | U15: =(O15-T15)/O15 -> 0.5
A16: 5 | B16: 大小头 | C16: DN125*100 | D16: 个 | E16: 3 | G16: 无货
A17: 6 | B17: 大小头 | C17: DN50*40 | D17: 个 | E17: 1 | G17: 8010071454 | H17: =VLOOKUP(G17,[1]LESSO管材!$C:$D,2,FALSE) -> 异径套(PPR 配件)印尼绿色 dn50x40 (1-1/2"x1-1/4") 联塑 | I17: =VLOOKUP(G17,[1]LESSO管材!$C:$E,3,FALSE) -> PPR Reducer dn50x40 (1-1/2"x1-1/4") Green(INA) - LESSO | K17: 个 | L17: 1 | M17: 联塑 | N17: =VLOOKUP(G17,[1]LESSO管材!$C:$L,10,FALSE) -> 7443 | O17: =N17*L17 -> 7443 | S17: {=INDEX([3]LESSO管材!$H:$H,MATCH(G17,[3]LESSO管材!$C:$C,0))} -> 6699 | T17: =S17*L17 -> 6699 | U17: =(O17-T17)/O17 -> 0.099959694
A18: 7 | B18: 盲板 | C18: DN100 | D18: 个 | E18: 1 | G18: 无货
A19: 8 | B19: 弯头 | C19: DN15 | D19: 个 | E19: 30 | G19: 8010071401 | H19: =VLOOKUP(G19,[1]LESSO管材!$C:$D,2,FALSE) -> 90°弯头(PPR 配件)印尼绿色 dn20 (1/2") 联塑 | I19: =VLOOKUP(G19,[1]LESSO管材!$C:$E,3,FALSE) -> PPR 90° Elbow dn20 (1/2") Green(INA) - LESSO | K19: 个 | L19: 30 | M19: 联塑 | N19: =VLOOKUP(G19,[1]LESSO管材!$C:$L,10,FALSE) -> 1233 | O19: =N19*L19 -> 36990 | S19: {=INDEX([3]LESSO管材!$H:$H,MATCH(G19,[3]LESSO管材!$C:$C,0))} -> 1110 | T19: =S19*L19 -> 33300 | U19: =(O19-T19)/O19 -> 0.099756691
A20: Total Excluding PPN不含税总价 | O20: =SUM(O3:O19) -> 4510101 | T20: =SUM(T3:T19) -> 3313245 | U20: =(O20-T20)/O20 -> 0.26537233
A21: 是否含PPN 11%/ Inc.or Exc.PPN 11% | O21: =O20*0.11 -> 496111.11
A22: 运费支付Freight Payment | O22: =N22*L22 -> 0
A23: Total Include PPN (11%)含税总价 | O23: =SUM(O20:O22) -> 5006212.1
A24: 发货地址Shipping Address
A25: 交货地点 / Franco / Pengiriman
A26: 付款方式 / Payment term
A27: Perusahaan yang memberikan penawaran 报价公司名称 | J27: Tanggal Penawaran 报价日期 | L27: 2026/2//2
A28: Petugas Pengisian Formulir 报单人员 | J28: Petugas Pengecekkan 审查人员
A29: TERMS & CONDITION 条款&条件
A30: No. 序号 | B30: Item 项目 | C30: Description 说明
A31: 1 | B31: 特备备注 | C31: LALAMOVE，运费客户支付（lalamove，Freight paid by the customer）
A32: 2 | B32: Delivery Time 交货时间 | C32: （付款后）几天交货时间为工厂发出时间
A33: 3 | B33: Packaging 包装
A34: 4 | B34: Guarantee 保证 | C34: 卖方保证所售商品的质量和安全，所售商品不存在任何缺陷或损坏。 买方需要在收到货物后最多 2 天检查已收到的货物。
A35: 5 | B35: Payment Methode 付款方式 | C35: 现款
B36: Beneficiery Account 收款账户
B37: Account Name 账户名称 | C37: PT. Vantsing International Group
B38: Account No账号 | C38: 268-0321666
B39: Bank 银行 | C39: Bank Central Asia KCP Grogol Muwardi
B40: Branch 分行 | C40: Jl. Muwardi I No.44, RT.1/RW.4, Grogol, Kec. Grogol petamburan, Kota Jakarta Barat, Daerah Khusus Ibukota Jakarta 11460
...

Sheet Sheet1
A1: {=_xlfn.UNIQUE(询价单!G:G)} -> 报价单 QUATATION
A2: Product number 产品编号
A3: 无货
A4: 8010071335 | B4: =SUMIFS(询价单!L:L,询价单!G:G,A4) -> 12 | C4: =SUMIFS('[2]Ketersediaan Stok Penjualan'!$W:$W,'[2]Ketersediaan Stok Penjualan'!$B:$B,A4) -> 48 | D4: =IF(C4>B4,"","STOCK")
A5: DS70232 | B5: =SUMIFS(询价单!L:L,询价单!G:G,A5) -> 12 | C5: =SUMIFS('[2]Ketersediaan Stok Penjualan'!$W:$W,'[2]Ketersediaan Stok Penjualan'!$B:$B,A5) -> 33 | D5: =IF(C5>B5,"","STOCK")
A6: 8010070747 | B6: =SUMIFS(询价单!L:L,询价单!G:G,A6) -> 12 | C6: =SUMIFS('[2]Ketersediaan Stok Penjualan'!$W:$W,'[2]Ketersediaan Stok Penjualan'!$B:$B,A6) -> 365 | D6: =IF(C6>B6,"","STOCK")
A7: 6900010080151 | B7: =SUMIFS(询价单!L:L,询价单!G:G,A7) -> 96 | C7: =SUMIFS('[2]Ketersediaan Stok Penjualan'!$W:$W,'[2]Ketersediaan Stok Penjualan'!$B:$B,A7) -> 208 | D7: =IF(C7>B7,"","STOCK")
A8: 8010071332 | B8: =SUMIFS(询价单!L:L,询价单!G:G,A8) -> 6 | C8: =SUMIFS('[2]Ketersediaan Stok Penjualan'!$W:$W,'[2]Ketersediaan Stok Penjualan'!$B:$B,A8) -> 201 | D8: =IF(C8>B8,"","STOCK")
A9: DS70235 | B9: =SUMIFS(询价单!L:L,询价单!G:G,A9) -> 6 | C9: =SUMIFS('[2]Ketersediaan Stok Penjualan'!$W:$W,'[2]Ketersediaan Stok Penjualan'!$B:$B,A9) -> 48 | D9: =IF(C9>B9,"","STOCK")
A10: 8010070750 | B10: =SUMIFS(询价单!L:L,询价单!G:G,A10) -> 6 | C10: =SUMIFS('[2]Ketersediaan Stok Penjualan'!$W:$W,'[2]Ketersediaan Stok Penjualan'!$B:$B,A10) -> 393 | D10: =IF(C10>B10,"","STOCK")
A11: 6900010080150 | B11: =SUMIFS(询价单!L:L,询价单!G:G,A11) -> 48 | C11: =SUMIFS('[2]Ketersediaan Stok Penjualan'!$W:$W,'[2]Ketersediaan Stok Penjualan'!$B:$B,A11) -> 1308 | D11: =IF(C11>B11,"","STOCK")
A12: 8010071331 | B12: =SUMIFS(询价单!L:L,询价单!G:G,A12) -> 6 | C12: =SUMIFS('[2]Ketersediaan Stok Penjualan'!$W:$W,'[2]Ketersediaan Stok Penjualan'!$B:$B,A12) -> 207 | D12: =IF(C12>B12,"","STOCK")
A13: DS70234 | B13: =SUMIFS(询价单!L:L,询价单!G:G,A13) -> 6 | C13: =SUMIFS('[2]Ketersediaan Stok Penjualan'!$W:$W,'[2]Ketersediaan Stok Penjualan'!$B:$B,A13) -> 44 | D13: =IF(C13>B13,"","STOCK")
A14: 8010070749 | B14: =SUMIFS(询价单!L:L,询价单!G:G,A14) -> 6 | C14: =SUMIFS('[2]Ketersediaan Stok Penjualan'!$W:$W,'[2]Ketersediaan Stok Penjualan'!$B:$B,A14) -> 600 | D14: =IF(C14>B14,"","STOCK")
A15: 8010071454 | B15: =SUMIFS(询价单!L:L,询价单!G:G,A15) -> 1 | C15: =SUMIFS('[2]Ketersediaan Stok Penjualan'!$W:$W,'[2]Ketersediaan Stok Penjualan'!$B:$B,A15) -> 268 | D15: =IF(C15>B15,"","STOCK")
A16: 8010071401 | B16: =SUMIFS(询价单!L:L,询价单!G:G,A16) -> 30 | C16: =SUMIFS('[2]Ketersediaan Stok Penjualan'!$W:$W,'[2]Ketersediaan Stok Penjualan'!$B:$B,A16) -> 4154 | D16: =IF(C16>B16,"","STOCK")
A17: 0
